#VRML_SIM R2023a utf8

EXTERNPROTO "https://raw.githubusercontent.com/cyberbotics/webots/R2022b/projects/objects/backgrounds/protos/TexturedBackground.proto"
EXTERNPROTO "https://raw.githubusercontent.com/cyberbotics/webots/R2022b/projects/objects/backgrounds/protos/TexturedBackgroundLight.proto"
EXTERNPROTO "https://raw.githubusercontent.com/cyberbotics/webots/R2022b/projects/objects/floors/protos/RectangleArena.proto"
EXTERNPROTO "https://raw.githubusercontent.com/cyberbotics/webots/R2022b/projects/appearances/protos/Parquetry.proto"
EXTERNPROTO "https://raw.githubusercontent.com/cyberbotics/webots/R2023a/projects/objects/factory/containers/protos/CardboardBox.proto"
EXTERNPROTO "https://raw.githubusercontent.com/cyberbotics/webots/R2023a/projects/objects/chairs/protos/WoodenChair.proto"
EXTERNPROTO "https://raw.githubusercontent.com/cyberbotics/webots/R2023a/projects/objects/kitchen/breakfast/protos/JamJar.proto"

WorldInfo {
}
Viewpoint {
  orientation 0.3358367650450293 -0.333400338008448 -0.8809414747075667 4.57777268798188
  position 0.2889252627169685 -7.0003474935129955 6.1855771888607025
}
TexturedBackground {
}
TexturedBackgroundLight {
}
RectangleArena {
  rotation 0 1 0 0
  floorSize 4 4
  floorTileSize 1 1
  floorAppearance Parquetry {
  }
}
DEF ROBOT Robot {
  translation 0 0 0.0399261
  children [
    DEF CASTOR_WHEEL Solid {
      translation -0.04 0 -0.03
      scale 0.1 0.1 0.1
      children [
        DEF CASTOR Shape {
          appearance PBRAppearance {
            baseColor 0.12549 0.290196 0.529412
            metalness 0
          }
          geometry Sphere {
            radius 0.1
          }
        }
      ]
      name "CASTOR_WHEEL"
      boundingObject USE CASTOR
      physics Physics {
      }
    }
    DEF BODY Shape {
      appearance PBRAppearance {
        baseColor 0.917647 0.145098 0.145098
        roughness 1
        metalness 0
      }
      geometry Box {
        size 0.1 0.1 0.05
      }
    }
    DEF WHEEL1 HingeJoint {
      jointParameters HingeJointParameters {
        axis 0 1 0
        anchor 0.02 0.06 0
      }
      device [
        RotationalMotor {
          name "left_wheel"
        }
      ]
      endPoint Solid {
        translation 0.020000000000000004 0.06 1.4548505635371076e-17
        rotation 1 4.429803545871984e-09 -4.429816185093063e-09 1.5707999999995534
        children [
          DEF WHEEL Shape {
            appearance PBRAppearance {
              baseColor 0.305882 0.898039 0.25098
              roughness 1
              metalness 0
            }
            geometry Cylinder {
              height 0.02
              radius 0.04
              subdivision 24
            }
          }
        ]
        boundingObject USE WHEEL
        physics Physics {
        }
      }
    }
    DEF WHEEL2 HingeJoint {
      jointParameters HingeJointParameters {
        axis 0 1 0
        anchor 0.02 -0.06 0
      }
      device [
        RotationalMotor {
          name "right_wheel"
        }
      ]
      endPoint Solid {
        translation 0.020000000000000004 -0.06 4.5071609150086356e-17
        rotation 1 -1.214901517000423e-09 1.2148984553257518e-09 1.5707999999995588
        children [
          USE WHEEL
        ]
        name "solid(1)"
        boundingObject USE WHEEL
        physics Physics {
        }
      }
    }
    DistanceSensor {
      translation 0.05 0 0
      rotation 0 0 1 1.0471996938995747
      name "ds_outer_left"
      lookupTable [
        0.02 0 0
        0.1 10 0
        0.5 50 0
      ]
    }
    DistanceSensor {
      translation 0.05 0 0
      rotation 0 0 1 0.5235996938995747
      name "ds_inner_left"
      lookupTable [
        0.02 0 0
        0.1 10 0
        0.5 50 0
      ]
    }
    DistanceSensor {
      translation 0.05 0 0
      children [
        Shape {
          appearance PBRAppearance {
            baseColor 0.184314 0.596078 0.847059
            roughness 1
            metalness 0
          }
          geometry Box {
            size 0.01 0.01 0.01
          }
        }
      ]
      name "ds_center"
      lookupTable [
        0.02 0 0
        0.1 10 0
        0.5 50 0
      ]
    }
    DistanceSensor {
      translation 0.05 0 0
      rotation 0 0 1 -0.5235996938995747
      name "ds_inner_right"
      lookupTable [
        0.02 0 0
        0.1 10 0
        0.5 50 0
      ]
    }
    DistanceSensor {
      translation 0.05 0 0
      rotation 0 0 1 -1.0472003061004251
      name "ds_outer_right"
      lookupTable [
        0.02 0 0
        0.1 10 0
        0.5 50 0
      ]
    }
    TouchSensor {
      translation 0.005 0 0
      boundingObject Box {
        size 0.115 0.15 0.05
      }
    }
  ]
  boundingObject USE BODY
  physics Physics {
  }
  controller "robot_supervisor_manager"
  supervisor TRUE
}
DEF TARGET Solid {
  translation 0.74 -0.0100038 0.001
  rotation 0 0 1 -1.5707953071795862
  scale 2 2 2
  children [
    Shape {
      appearance Appearance {
        material Material {
        }
        texture ImageTexture {
          url [
            "https://avatars.githubusercontent.com/u/57842071?s=256"
          ]
        }
      }
      geometry Plane {
        size 0.12 0.12
      }
    }
  ]
  name "target"
}
DEF OBSTACLES Group {
  children [
    DEF OBSTACLE_CBL1 CardboardBox {
      translation 5.5 0 0.051
      name "cardboard box long 1"
      size 0.1 0.4 0.1
    }
    DEF OBSTACLE_CBL2 CardboardBox {
      translation 5.62 0 0.051
      name "cardboard box long 2"
      size 0.1 0.4 0.1
    }
    DEF OBSTACLE_CBL3 CardboardBox {
      translation 5.74 0 0.051
      name "cardboard box long 3"
      size 0.1 0.4 0.1
    }
    DEF OBSTACLE_CBL4 CardboardBox {
      translation 5.86 0 0.051
      name "cardboard box long 4"
      size 0.1 0.4 0.1
    }
    DEF OBSTACLE_CB1 CardboardBox {
      translation 5.5 0.29 0.051
      name "cardboard box 1"
      size 0.1 0.1 0.1
    }
    DEF OBSTACLE_CB2 CardboardBox {
      translation 5.62 0.29 0.051
      name "cardboard box 2"
      size 0.1 0.1 0.1
    }
    DEF OBSTACLE_CB3 CardboardBox {
      translation 5.74 0.29 0.051
      name "cardboard box 3"
      size 0.1 0.1 0.1
    }
    DEF OBSTACLE_CB4 CardboardBox {
      translation 5.86 0.29 0.051
      name "cardboard box 4"
      size 0.1 0.1 0.1
    }
    DEF OBSTACLE_CBLA1 CardboardBox {
      translation 5.86 0.68 0.051
      name "cardboard box large 1"
      size 0.4 0.4 0.1
    }
    DEF OBSTACLE_CBLA2 CardboardBox {
      translation 5.86 1.13 0.051
      name "cardboard box large 2"
      size 0.4 0.4 0.1
    }
    DEF OBSTACLE_CBLA3 CardboardBox {
      translation 5.86 1.59 0.051
      name "cardboard box large 3"
      size 0.4 0.4 0.1
    }
    DEF OBSTACLE_CBLA4 CardboardBox {
      translation 5.86 2.06 0.051
      name "cardboard box large 4"
      size 0.4 0.4 0.1
    }
    DEF OBSTACLE_C1 WoodenChair {
      translation 6.46 0 0
      name "wooden chair 1"
    }
    DEF OBSTACLE_C2 WoodenChair {
      translation 6.46 0.46 0
      name "wooden chair 2"
    }
    DEF OBSTACLE_C3 WoodenChair {
      translation 6.46 0.91 0
      name "wooden chair 3"
    }
    DEF OBSTACLE_C4 WoodenChair {
      translation 6.46 1.38 0
      name "wooden chair 4"
    }
    DEF OBSTACLE_JJ1 JamJar {
      translation 5.31 -0.16 0
      name "jam jar 1"
    }
    DEF OBSTACLE_JJ2 JamJar {
      translation 5.31 -0.05 0
      name "jam jar 2"
    }
    DEF OBSTACLE_JJ3 JamJar {
      translation 5.31 0.06 0
      name "jam jar 3"
    }
    DEF OBSTACLE_JJ4 JamJar {
      translation 5.31 0.16 0
      name "jam jar 4"
    }
  ]
}
DEF PATH Group {
  children [
    DEF p0 Solid {
      translation 5.13 6.4235e-07 0.001
      rotation 0 0 1 -1.5707953071795862
      children [
        Shape {
          appearance Appearance {
            material Material {
              transparency 0.75
            }
            texture ImageTexture {
              url [
                "https://avatars.githubusercontent.com/u/57842071?s=256"
              ]
            }
          }
          geometry Plane {
            size 0.12 0.12
          }
        }
      ]
      name "p"
    }
    DEF p1 Solid {
      translation 5.13 0.120001 0.001
      rotation 0 0 1 -1.5707953071795862
      children [
        Shape {
          appearance Appearance {
            material Material {
              transparency 0.75
            }
            texture ImageTexture {
              url [
                "https://avatars.githubusercontent.com/u/57842071?s=256"
              ]
            }
          }
          geometry Plane {
            size 0.12 0.12
          }
        }
      ]
      name "p(1)"
    }
    DEF p2 Solid {
      translation 5.13 0.250001 0.001
      rotation 0 0 1 -1.5707953071795862
      children [
        Shape {
          appearance Appearance {
            material Material {
              transparency 0.75
            }
            texture ImageTexture {
              url [
                "https://avatars.githubusercontent.com/u/57842071?s=256"
              ]
            }
          }
          geometry Plane {
            size 0.12 0.12
          }
        }
      ]
      name "p(2)"
    }
    DEF p3 Solid {
      translation 5.13 0.360001 0.001
      rotation 0 0 1 -1.5707953071795862
      children [
        Shape {
          appearance Appearance {
            material Material {
              transparency 0.75
            }
            texture ImageTexture {
              url [
                "https://avatars.githubusercontent.com/u/57842071?s=256"
              ]
            }
          }
          geometry Plane {
            size 0.12 0.12
          }
        }
      ]
      name "p(3)"
    }
    DEF p4 Solid {
      translation 5.13 0.490001 0.001
      rotation 0 0 1 -1.5707953071795862
      children [
        Shape {
          appearance Appearance {
            material Material {
              transparency 0.75
            }
            texture ImageTexture {
              url [
                "https://avatars.githubusercontent.com/u/57842071?s=256"
              ]
            }
          }
          geometry Plane {
            size 0.12 0.12
          }
        }
      ]
      name "p(4)"
    }
    DEF p5 Solid {
      translation 5.13 0.610001 0.001
      rotation 0 0 1 -1.5707953071795862
      children [
        Shape {
          appearance Appearance {
            material Material {
              transparency 0.75
            }
            texture ImageTexture {
              url [
                "https://avatars.githubusercontent.com/u/57842071?s=256"
              ]
            }
          }
          geometry Plane {
            size 0.12 0.12
          }
        }
      ]
      name "p(5)"
    }
    DEF p6 Solid {
      translation 5.13 0.730001 0.001
      rotation 0 0 1 -1.5707953071795862
      children [
        Shape {
          appearance Appearance {
            material Material {
              transparency 0.75
            }
            texture ImageTexture {
              url [
                "https://avatars.githubusercontent.com/u/57842071?s=256"
              ]
            }
          }
          geometry Plane {
            size 0.12 0.12
          }
        }
      ]
      name "p(6)"
    }
    DEF p7 Solid {
      translation 5.13 0.850001 0.001
      rotation 0 0 1 -1.5707953071795862
      children [
        Shape {
          appearance Appearance {
            material Material {
              transparency 0.75
            }
            texture ImageTexture {
              url [
                "https://avatars.githubusercontent.com/u/57842071?s=256"
              ]
            }
          }
          geometry Plane {
            size 0.12 0.12
          }
        }
      ]
      name "p(7)"
    }
    DEF p8 Solid {
      translation 5.13 0.970001 0.001
      rotation 0 0 1 -1.5707953071795862
      children [
        Shape {
          appearance Appearance {
            material Material {
              transparency 0.75
            }
            texture ImageTexture {
              url [
                "https://avatars.githubusercontent.com/u/57842071?s=256"
              ]
            }
          }
          geometry Plane {
            size 0.12 0.12
          }
        }
      ]
      name "p(8)"
    }
    DEF p9 Solid {
      translation 5.13 1.1 0.001
      rotation 0 0 1 -1.5707953071795862
      children [
        Shape {
          appearance Appearance {
            material Material {
              transparency 0.75
            }
            texture ImageTexture {
              url [
                "https://avatars.githubusercontent.com/u/57842071?s=256"
              ]
            }
          }
          geometry Plane {
            size 0.12 0.12
          }
        }
      ]
      name "p(9)"
    }
    DEF p10 Solid {
      translation 5.13 1.23 0.001
      rotation 0 0 1 -1.5707953071795862
      children [
        Shape {
          appearance Appearance {
            material Material {
              transparency 0.75
            }
            texture ImageTexture {
              url [
                "https://avatars.githubusercontent.com/u/57842071?s=256"
              ]
            }
          }
          geometry Plane {
            size 0.12 0.12
          }
        }
      ]
      name "p(10)"
    }
    DEF p11 Solid {
      translation 5.13 1.36 0.001
      rotation 0 0 1 -1.5707953071795862
      children [
        Shape {
          appearance Appearance {
            material Material {
              transparency 0.75
            }
            texture ImageTexture {
              url [
                "https://avatars.githubusercontent.com/u/57842071?s=256"
              ]
            }
          }
          geometry Plane {
            size 0.12 0.12
          }
        }
      ]
      name "p(11)"
    }
    DEF p12 Solid {
      translation 5.13 1.49 0.001
      rotation 0 0 1 -1.5707953071795862
      children [
        Shape {
          appearance Appearance {
            material Material {
              transparency 0.75
            }
            texture ImageTexture {
              url [
                "https://avatars.githubusercontent.com/u/57842071?s=256"
              ]
            }
          }
          geometry Plane {
            size 0.12 0.12
          }
        }
      ]
      name "p(12)"
    }
    DEF p13 Solid {
      translation 5.13 1.61 0.001
      rotation 0 0 1 -1.5707953071795862
      children [
        Shape {
          appearance Appearance {
            material Material {
              transparency 0.75
            }
            texture ImageTexture {
              url [
                "https://avatars.githubusercontent.com/u/57842071?s=256"
              ]
            }
          }
          geometry Plane {
            size 0.12 0.12
          }
        }
      ]
      name "p(13)"
    }
    DEF p14 Solid {
      translation 5.13 1.74 0.001
      rotation 0 0 1 -1.5707953071795862
      children [
        Shape {
          appearance Appearance {
            material Material {
              transparency 0.75
            }
            texture ImageTexture {
              url [
                "https://avatars.githubusercontent.com/u/57842071?s=256"
              ]
            }
          }
          geometry Plane {
            size 0.12 0.12
          }
        }
      ]
      name "p(14)"
    }
    DEF p15 Solid {
      translation 5.13 1.86 0.001
      rotation 0 0 1 -1.5707953071795862
      children [
        Shape {
          appearance Appearance {
            material Material {
              transparency 0.75
            }
            texture ImageTexture {
              url [
                "https://avatars.githubusercontent.com/u/57842071?s=256"
              ]
            }
          }
          geometry Plane {
            size 0.12 0.12
          }
        }
      ]
      name "p(15)"
    }
  ]
}
