#VRML_SIM R2023a utf8

EXTERNPROTO "https://raw.githubusercontent.com/cyberbotics/webots/R2022b/projects/objects/backgrounds/protos/TexturedBackground.proto"
EXTERNPROTO "https://raw.githubusercontent.com/cyberbotics/webots/R2022b/projects/objects/backgrounds/protos/TexturedBackgroundLight.proto"
EXTERNPROTO "https://raw.githubusercontent.com/cyberbotics/webots/R2022b/projects/objects/floors/protos/RectangleArena.proto"
EXTERNPROTO "https://raw.githubusercontent.com/cyberbotics/webots/R2022b/projects/appearances/protos/Parquetry.proto"
EXTERNPROTO "https://raw.githubusercontent.com/cyberbotics/webots/R2023a/projects/objects/factory/containers/protos/CardboardBox.proto"
EXTERNPROTO "https://raw.githubusercontent.com/cyberbotics/webots/R2023a/projects/objects/chairs/protos/WoodenChair.proto"
EXTERNPROTO "https://raw.githubusercontent.com/cyberbotics/webots/R2023a/projects/objects/kitchen/breakfast/protos/JamJar.proto"

WorldInfo {
}
Viewpoint {
  orientation 0.3160221117267843 -0.31809431674893923 -0.8938378099810779 4.605858620620651
  position -0.12897269160750136 -8.781719362907548 6.545164249791947
}
TexturedBackground {
}
TexturedBackgroundLight {
}
RectangleArena {
  rotation 0 1 0 0
  floorSize 10 10
  floorTileSize 1 1
  floorAppearance Parquetry {
  }
  wallHeight 0.5
}
DEF ROBOT Robot {
  translation 0 0 0.0399261
  children [
    DEF CASTOR_WHEEL Solid {
      translation -0.04 0 -0.03
      scale 0.1 0.1 0.1
      children [
        DEF CASTOR Shape {
          appearance PBRAppearance {
            baseColor 0.12549 0.290196 0.529412
            metalness 0
          }
          geometry Sphere {
            radius 0.1
          }
        }
      ]
      name "CASTOR_WHEEL"
      boundingObject USE CASTOR
      physics Physics {
      }
    }
    DEF BODY Shape {
      appearance PBRAppearance {
        baseColor 0.917647 0.145098 0.145098
        roughness 1
        metalness 0
      }
      geometry Box {
        size 0.1 0.1 0.05
      }
    }
    DEF WHEEL1 HingeJoint {
      jointParameters HingeJointParameters {
        axis 0 1 0
        anchor 0.02 0.06 0
      }
      device [
        RotationalMotor {
          name "left_wheel"
        }
      ]
      endPoint Solid {
        translation 0.020000000000000004 0.06 -1.2287559033515813e-18
        rotation 1 5.247351061897109e-09 -5.247370315120555e-09 1.5707999999999809
        children [
          DEF WHEEL Shape {
            appearance PBRAppearance {
              baseColor 0.305882 0.898039 0.25098
              roughness 1
              metalness 0
            }
            geometry Cylinder {
              height 0.02
              radius 0.04
              subdivision 24
            }
          }
        ]
        boundingObject USE WHEEL
        physics Physics {
        }
      }
    }
    DEF WHEEL2 HingeJoint {
      jointParameters HingeJointParameters {
        axis 0 1 0
        anchor 0.02 -0.06 0
      }
      device [
        RotationalMotor {
          name "right_wheel"
        }
      ]
      endPoint Solid {
        translation 0.020000000000000004 -0.06 1.8205593176878545e-18
        rotation 1 -5.87933141689783e-12 5.880008386053733e-12 1.5707999999999889
        children [
          USE WHEEL
        ]
        name "solid(1)"
        boundingObject USE WHEEL
        physics Physics {
        }
      }
    }
    DistanceSensor {
      translation 0.05 0 0
      rotation 0 0 1 1.0471996938995747
      name "ds_outer_left"
      lookupTable [
        0.02 0 0
        0.1 10 0
        0.5 50 0
        2.55 255 0
      ]
    }
    DistanceSensor {
      translation 0.05 0 0
      rotation 0 0 1 0.5235996938995747
      name "ds_inner_left"
      lookupTable [
        0.02 0 0
        0.1 10 0
        0.5 50 0
        2.55 255 0
      ]
    }
    DistanceSensor {
      translation 0.05 0 0
      children [
        Shape {
          appearance PBRAppearance {
            baseColor 0.184314 0.596078 0.847059
            roughness 1
            metalness 0
          }
          geometry Box {
            size 0.01 0.01 0.01
          }
        }
      ]
      name "ds_center"
      lookupTable [
        0.02 0 0
        0.1 10 0
        0.5 50 0
        2.55 255 0
      ]
    }
    DistanceSensor {
      translation 0.05 0 0
      rotation 0 0 1 -0.5235996938995747
      name "ds_inner_right"
      lookupTable [
        0.02 0 0
        0.1 10 0
        0.5 50 0
        2.55 255 0
      ]
    }
    DistanceSensor {
      translation 0.05 0 0
      rotation 0 0 1 -1.0472003061004251
      name "ds_outer_right"
      lookupTable [
        0.02 0 0
        0.1 10 0
        0.5 50 0
        2.55 255 0
      ]
    }
    TouchSensor {
      translation 0.005 0 0
      boundingObject Box {
        size 0.115 0.15 0.05
      }
    }
  ]
  boundingObject USE BODY
  physics Physics {
  }
  controller "robot_supervisor_manager"
  supervisor TRUE
}
DEF TARGET Solid {
  translation 0.74 -3.83376e-06 0.001
  rotation 0 0 1 -1.5707953071795862
  children [
    Shape {
      appearance Appearance {
        material Material {
        }
        texture ImageTexture {
          url [
            "https://avatars.githubusercontent.com/u/57842071?s=256"
          ]
        }
      }
      geometry Plane {
        size 0.12 0.12
      }
    }
  ]
  name "target"
}
DEF OBSTACLES Transform {
  children [
    DEF OBSTACLE_CBL1 CardboardBox {
      translation 5.5 0 0.051
      name "cardboard box long 1"
      size 0.1 0.4 0.1
    }
    DEF OBSTACLE_CBL2 CardboardBox {
      translation 5.62 0 0.051
      name "cardboard box long 2"
      size 0.1 0.4 0.1
    }
    DEF OBSTACLE_CBL3 CardboardBox {
      translation 5.74 0 0.051
      name "cardboard box long 3"
      size 0.1 0.4 0.1
    }
    DEF OBSTACLE_CBL4 CardboardBox {
      translation 5.86 0 0.051
      name "cardboard box long 4"
      size 0.1 0.4 0.1
    }
    DEF OBSTACLE_CB1 CardboardBox {
      translation 5.5 0.29 0.051
      name "cardboard box 1"
      size 0.1 0.1 0.1
    }
    DEF OBSTACLE_CB2 CardboardBox {
      translation 5.62 0.29 0.051
      name "cardboard box 2"
      size 0.1 0.1 0.1
    }
    DEF OBSTACLE_CB3 CardboardBox {
      translation 5.74 0.29 0.051
      name "cardboard box 3"
      size 0.1 0.1 0.1
    }
    DEF OBSTACLE_CB4 CardboardBox {
      translation 5.86 0.29 0.051
      name "cardboard box 4"
      size 0.1 0.1 0.1
    }
    DEF OBSTACLE_CBLA1 CardboardBox {
      translation 5.86 0.68 0.051
      name "cardboard box large 1"
      size 0.4 0.4 0.1
    }
    DEF OBSTACLE_CBLA2 CardboardBox {
      translation 5.86 1.13 0.051
      name "cardboard box large 2"
      size 0.4 0.4 0.1
    }
    DEF OBSTACLE_CBLA3 CardboardBox {
      translation 5.86 1.59 0.051
      name "cardboard box large 3"
      size 0.4 0.4 0.1
    }
    DEF OBSTACLE_CBLA4 CardboardBox {
      translation 5.86 2.06 0.051
      name "cardboard box large 4"
      size 0.4 0.4 0.1
    }
    DEF OBSTACLE_C1 WoodenChair {
      translation 6.46 0 0
      name "wooden chair 1"
    }
    DEF OBSTACLE_C2 WoodenChair {
      translation 6.46 0.46 0
      name "wooden chair 2"
    }
    DEF OBSTACLE_C3 WoodenChair {
      translation 6.46 0.91 0
      name "wooden chair 3"
    }
    DEF OBSTACLE_C4 WoodenChair {
      translation 6.46 1.38 0
      name "wooden chair 4"
    }
    DEF OBSTACLE_JJ1 JamJar {
      translation 5.31 -0.16 0
      name "jam jar 1"
    }
    DEF OBSTACLE_JJ2 JamJar {
      translation 5.31 -0.05 0
      name "jam jar 2"
    }
    DEF OBSTACLE_JJ3 JamJar {
      translation 5.31 0.06 0
      name "jam jar 3"
    }
    DEF OBSTACLE_JJ4 JamJar {
      translation 5.31 0.16 0
      name "jam jar 4"
    }
  ]
}
