#VRML_SIM R2023a utf8

EXTERNPROTO "https://raw.githubusercontent.com/cyberbotics/webots/R2022b/projects/objects/backgrounds/protos/TexturedBackground.proto"
EXTERNPROTO "https://raw.githubusercontent.com/cyberbotics/webots/R2022b/projects/objects/backgrounds/protos/TexturedBackgroundLight.proto"
EXTERNPROTO "https://raw.githubusercontent.com/cyberbotics/webots/R2022b/projects/objects/floors/protos/RectangleArena.proto"
EXTERNPROTO "https://raw.githubusercontent.com/cyberbotics/webots/R2022b/projects/appearances/protos/Parquetry.proto"
EXTERNPROTO "https://raw.githubusercontent.com/cyberbotics/webots/R2023a/projects/objects/factory/containers/protos/CardboardBox.proto"
EXTERNPROTO "https://raw.githubusercontent.com/cyberbotics/webots/R2023a/projects/objects/chairs/protos/WoodenChair.proto"

WorldInfo {
}
Viewpoint {
  orientation 0.011543883175480902 -0.9999230464329063 0.0045431237675012245 4.6643240189671555
  position 0.7713688512155992 -0.12005334548594844 9.55738441446393
}
TexturedBackground {
}
TexturedBackgroundLight {
}
RectangleArena {
  rotation 0 1 0 0
  floorSize 10 10
  floorTileSize 1 1
  floorAppearance Parquetry {
  }
  wallHeight 0.5
}
DEF ROBOT Robot {
  translation 0 0 0.0399261
  children [
    DEF CASTOR_WHEEL Solid {
      translation -0.04 0 -0.03
      scale 0.1 0.1 0.1
      children [
        DEF CASTOR Shape {
          appearance PBRAppearance {
            baseColor 0.12549 0.290196 0.529412
            metalness 0
          }
          geometry Sphere {
            radius 0.1
          }
        }
      ]
      name "CASTOR_WHEEL"
      boundingObject USE CASTOR
      physics Physics {
      }
    }
    DEF BODY Shape {
      appearance PBRAppearance {
        baseColor 0.917647 0.145098 0.145098
        roughness 1
        metalness 0
      }
      geometry Box {
        size 0.1 0.1 0.05
      }
    }
    DEF WHEEL1 HingeJoint {
      jointParameters HingeJointParameters {
        axis 0 1 0
        anchor 0.02 0.06 0
      }
      device [
        RotationalMotor {
          name "left_wheel"
        }
      ]
      endPoint Solid {
        translation 0.020000000000000004 0.06 1.0093995695757107e-19
        rotation 1 5.826156311331979e-09 -5.826177075766609e-09 1.5707999999999882
        children [
          DEF WHEEL Shape {
            appearance PBRAppearance {
              baseColor 0.305882 0.898039 0.25098
              roughness 1
              metalness 0
            }
            geometry Cylinder {
              height 0.02
              radius 0.04
              subdivision 24
            }
          }
        ]
        boundingObject USE WHEEL
        physics Physics {
        }
      }
    }
    DEF WHEEL2 HingeJoint {
      jointParameters HingeJointParameters {
        axis 0 1 0
        anchor 0.02 -0.06 0
      }
      device [
        RotationalMotor {
          name "right_wheel"
        }
      ]
      endPoint Solid {
        translation 0.020000000000000004 -0.06 1.1160006632069383e-18
        rotation 1 2.455282918651195e-10 -2.455285273785557e-10 1.570799999999996
        children [
          USE WHEEL
        ]
        name "solid(1)"
        boundingObject USE WHEEL
        physics Physics {
        }
      }
    }
    DistanceSensor {
      translation 0.05 0 0
      rotation 0 0 1 1.0471996938995747
      name "ds_outer_left"
      lookupTable [
        0.02 0 0
        0.1 10 0
        0.5 50 0
        2.55 255 0
      ]
    }
    DistanceSensor {
      translation 0.05 0 0
      rotation 0 0 1 0.5235996938995747
      name "ds_inner_left"
      lookupTable [
        0.02 0 0
        0.1 10 0
        0.5 50 0
        2.55 255 0
      ]
    }
    DistanceSensor {
      translation 0.05 0 0
      children [
        Shape {
          appearance PBRAppearance {
            baseColor 0.184314 0.596078 0.847059
            roughness 1
            metalness 0
          }
          geometry Box {
            size 0.01 0.01 0.01
          }
        }
      ]
      name "ds_center"
      lookupTable [
        0.02 0 0
        0.1 10 0
        0.5 50 0
        2.55 255 0
      ]
    }
    DistanceSensor {
      translation 0.05 0 0
      rotation 0 0 1 -0.5235996938995747
      name "ds_inner_right"
      lookupTable [
        0.02 0 0
        0.1 10 0
        0.5 50 0
        2.55 255 0
      ]
    }
    DistanceSensor {
      translation 0.05 0 0
      rotation 0 0 1 -1.0472003061004251
      name "ds_outer_right"
      lookupTable [
        0.02 0 0
        0.1 10 0
        0.5 50 0
        2.55 255 0
      ]
    }
  ]
  boundingObject USE BODY
  physics Physics {
  }
  controller "robot_supervisor_manager"
  supervisor TRUE
}
DEF TARGET Solid {
  translation 0.74 -3.83376e-06 0.001
  rotation 0 0 1 -1.5707953071795862
  children [
    Shape {
      appearance Appearance {
        material Material {
        }
        texture ImageTexture {
          url [
            "https://avatars.githubusercontent.com/u/57842071?s=256"
          ]
        }
      }
      geometry Plane {
        size 0.12 0.12
      }
    }
  ]
  name "target"
}
DEF CBL1 CardboardBox {
  translation 5.5 0 0.051
  name "cardboard box long 1"
  size 0.1 0.6 0.1
}
DEF CBL2 CardboardBox {
  translation 5.62 0 0.051
  name "cardboard box long 2"
  size 0.1 0.6 0.1
}
DEF CBL3 CardboardBox {
  translation 5.74 0 0.051
  name "cardboard box long 3"
  size 0.1 0.6 0.1
}
DEF CBL4 CardboardBox {
  translation 5.86 0 0.051
  name "cardboard box long 4"
  size 0.1 0.6 0.1
}
DEF CB1 CardboardBox {
  translation 5.61 0.86 0.051
  name "cardboard box 1"
  size 0.1 0.1 0.1
}
DEF CB2 CardboardBox {
  translation 5.5 0.86 0.051
  name "cardboard box 2"
  size 0.1 0.1 0.1
}
DEF C1 WoodenChair {
  translation 6.46 0 0
  name "wooden chair 1"
}
DEF C2 WoodenChair {
  translation 6.46 0.87 0
  name "wooden chair 2"
}
