#VRML_SIM R2023a utf8

EXTERNPROTO "https://raw.githubusercontent.com/cyberbotics/webots/R2022b/projects/objects/backgrounds/protos/TexturedBackground.proto"
EXTERNPROTO "https://raw.githubusercontent.com/cyberbotics/webots/R2022b/projects/objects/backgrounds/protos/TexturedBackgroundLight.proto"
EXTERNPROTO "https://raw.githubusercontent.com/cyberbotics/webots/R2022b/projects/objects/floors/protos/RectangleArena.proto"
EXTERNPROTO "https://raw.githubusercontent.com/cyberbotics/webots/R2022b/projects/appearances/protos/Parquetry.proto"
EXTERNPROTO "https://raw.githubusercontent.com/cyberbotics/webots/R2023a/projects/objects/factory/containers/protos/CardboardBox.proto"
EXTERNPROTO "https://raw.githubusercontent.com/cyberbotics/webots/R2023a/projects/objects/chairs/protos/WoodenChair.proto"
EXTERNPROTO "https://raw.githubusercontent.com/cyberbotics/webots/R2023a/projects/objects/kitchen/breakfast/protos/JamJar.proto"

WorldInfo {
}
DEF VIEWPOINT Viewpoint {
  orientation -0.38376571817432 0.3845518328444645 0.8395497373057249 1.7427853198470402
  position 0.12857611495215343 -6.721697079718461 7.536561888615677
  follow "robot"
}
TexturedBackground {
}
TexturedBackgroundLight {
}
RectangleArena {
  rotation 0 1 0 0
  floorSize 3.6 3.6
  floorTileSize 1 1
  floorAppearance Parquetry {
  }
}
DEF ROBOT Robot {
  translation 0 0 0.0399261
  children [
    DEF CASTOR_WHEEL_FRONT Solid {
      translation 0.04 0 -0.03
      scale 0.1 0.1 0.1
      children [
        DEF CASTOR Shape {
          appearance PBRAppearance {
            baseColor 0.12549 0.290196 0.529412
            metalness 0
          }
          geometry Sphere {
            radius 0.1
          }
        }
      ]
      name "CASTOR_WHEEL"
      boundingObject USE CASTOR
      physics Physics {
      }
    }
    DEF CASTOR_WHEEL_BACK Solid {
      translation -0.04 0 -0.03
      scale 0.1 0.1 0.1
      children [
        DEF CASTOR Shape {
          appearance PBRAppearance {
            baseColor 0.12549 0.290196 0.529412
            metalness 0
          }
          geometry Sphere {
            radius 0.1
          }
        }
      ]
      name "CASTOR_WHEEL(1)"
      boundingObject USE CASTOR
      physics Physics {
      }
    }
    DEF BODY Shape {
      appearance PBRAppearance {
        baseColor 0.917647 0.145098 0.145098
        roughness 1
        metalness 0
      }
      geometry Box {
        size 0.1 0.1 0.05
      }
    }
    DEF WHEEL1 HingeJoint {
      jointParameters HingeJointParameters {
        axis 0 1 0
        anchor 0 0.06 0
      }
      device [
        RotationalMotor {
          name "left_wheel"
        }
      ]
      endPoint Solid {
        translation -1.8271458147876748e-29 0.06 1.3969099999999822e-17
        rotation 1 4.476893101656486e-09 -4.476898759199882e-09 1.5707999999993825
        children [
          DEF WHEEL Shape {
            appearance PBRAppearance {
              baseColor 0.305882 0.898039 0.25098
              roughness 1
              metalness 0
            }
            geometry Cylinder {
              height 0.02
              radius 0.04
              subdivision 24
            }
          }
        ]
        boundingObject USE WHEEL
        physics Physics {
        }
      }
    }
    DEF WHEEL2 HingeJoint {
      jointParameters HingeJointParameters {
        axis 0 1 0
        anchor 0 -0.06 0
      }
      device [
        RotationalMotor {
          name "right_wheel"
        }
      ]
      endPoint Solid {
        translation -2.968476615265604e-28 -0.06 4.5013100000000055e-17
        rotation 1 -1.218209392652112e-09 1.218191764706311e-09 1.5707999999994025
        children [
          USE WHEEL
        ]
        name "solid(1)"
        boundingObject USE WHEEL
        physics Physics {
        }
      }
    }
    DEF DS Group {
      children [
        DistanceSensor {
          translation 0.051 0 0
          rotation 0 0 1 1.570796327
          children [
            Shape {
              appearance PBRAppearance {
              }
              geometry Box {
                size 0.01 0.01 0.01
              }
            }
          ]
          name "distance sensor(0)"
          lookupTable [
            0.0775 0 0
            0.4 40 0
          ]
          type "sonar"
        }
        DistanceSensor {
          translation 0.051 0 0
          rotation 0 0 1 1.308996939
          name "distance sensor(1)"
          lookupTable [
            0.05 0 0
            0.4 40 0
          ]
          type "sonar"
        }
        DistanceSensor {
          translation 0.051 0 0
          rotation 0 0 1 1.047197551
          name "distance sensor(2)"
          lookupTable [
            0.025 0 0
            0.4 40 0
          ]
          type "sonar"
        }
        DistanceSensor {
          translation 0.051 0 0
          rotation 0 0 1 0.785398163
          name "distance sensor(3)"
          lookupTable [
            0.018 0 0
            0.4 40 0
          ]
          type "sonar"
        }
        DistanceSensor {
          translation 0.051 0 0
          rotation 0 0 1 0.523598776
          name "distance sensor(4)"
          lookupTable [
            0.015 0 0
            0.4 40 0
          ]
          type "sonar"
        }
        DistanceSensor {
          translation 0.051 0 0
          rotation 0 0 1 0.2617993877991494
          name "distance sensor(5)"
          lookupTable [
            0.0138 0 0
            0.4 40 0
          ]
          type "sonar"
        }
        DistanceSensor {
          translation 0.051 0 0
          name "distance sensor(6)"
          lookupTable [
            0.0135 0 0
            0.4 40 0
          ]
          type "sonar"
        }
        DistanceSensor {
          translation 0.051 0 0
          rotation 0 0 1 -0.261799
          name "distance sensor(7)"
          lookupTable [
            0.0138 0 0
            0.4 40 0
          ]
          type "sonar"
        }
        DistanceSensor {
          translation 0.051 0 0
          rotation 0 0 1 -0.523598776
          name "distance sensor(8)"
          lookupTable [
            0.015 0 0
            0.4 40 0
          ]
          type "sonar"
        }
        DistanceSensor {
          translation 0.051 0 0
          rotation 0 0 1 -0.785398163
          name "distance sensor(9)"
          lookupTable [
            0.018 0 0
            0.4 40 0
          ]
          type "sonar"
        }
        DistanceSensor {
          translation 0.051 0 0
          rotation 0 0 1 -1.047197551
          name "distance sensor(10)"
          lookupTable [
            0.025 0 0
            0.4 40 0
          ]
          type "sonar"
        }
        DistanceSensor {
          translation 0.051 0 0
          rotation 0 0 1 -1.309
          name "distance sensor(11)"
          lookupTable [
            0.05 0 0
            0.4 40 0
          ]
          type "sonar"
        }
        DistanceSensor {
          translation 0.051 0 0
          rotation 0 0 1 -1.570796327
          name "distance sensor(12)"
          lookupTable [
            0.0775 0 0
            0.4 40 0
          ]
          type "sonar"
        }
      ]
    }
    TouchSensor {
      translation 0.0515 0 0
      boundingObject Box {
        size 0.02 0.15 0.02
      }
    }
  ]
  boundingObject USE BODY
  physics Physics {
  }
  controller "robot_supervisor_manager"
  supervisor TRUE
}
DEF TARGET Solid {
  translation 0.74 -0.0100038 0.001
  rotation 0 0 1 -1.5707953071795862
  scale 2 2 2
  children [
    Shape {
      appearance Appearance {
        material Material {
        }
        texture ImageTexture {
          url [
            "https://avatars.githubusercontent.com/u/57842071?s=256"
          ]
        }
      }
      geometry Plane {
        size 0.12 0.12
      }
    }
  ]
  name "target"
}
DEF OBSTACLES Group {
  children [
    DEF OBSTACLE_CBL1 CardboardBox {
      translation 5.5 0 0.051
      name "cardboard box long 1"
      size 0.1 0.4 0.1
    }
    DEF OBSTACLE_CBL2 CardboardBox {
      translation 5.62 0 0.051
      name "cardboard box long 2"
      size 0.1 0.4 0.1
    }
    DEF OBSTACLE_CBL3 CardboardBox {
      translation 5.74 0 0.051
      name "cardboard box long 3"
      size 0.1 0.4 0.1
    }
    DEF OBSTACLE_CBL4 CardboardBox {
      translation 5.98 0 0.051
      name "cardboard box long 4"
      size 0.1 0.4 0.1
    }
    DEF OBSTACLE_CBL5 CardboardBox {
      translation 5.86 0 0.051
      name "cardboard box long 5"
      size 0.1 0.4 0.1
    }
    DEF OBSTACLE_CB1 CardboardBox {
      translation 5.5 0.29 0.051
      name "cardboard box 1"
      size 0.1 0.1 0.1
    }
    DEF OBSTACLE_CB2 CardboardBox {
      translation 5.62 0.29 0.051
      name "cardboard box 2"
      size 0.1 0.1 0.1
    }
    DEF OBSTACLE_CB3 CardboardBox {
      translation 5.74 0.29 0.051
      name "cardboard box 3"
      size 0.1 0.1 0.1
    }
    DEF OBSTACLE_CB4 CardboardBox {
      translation 5.86 0.29 0.051
      name "cardboard box 4"
      size 0.1 0.1 0.1
    }
    DEF OBSTACLE_CB5 CardboardBox {
      translation 5.98 0.29 0.051
      name "cardboard box 5"
      size 0.1 0.1 0.1
    }
    DEF OBSTACLE_CBLA1 CardboardBox {
      translation 5.86 0.68 0.051
      name "cardboard box large 1"
      size 0.4 0.4 0.1
    }
    DEF OBSTACLE_CBLA2 CardboardBox {
      translation 5.86 1.13 0.051
      name "cardboard box large 2"
      size 0.4 0.4 0.1
    }
    DEF OBSTACLE_CBLA3 CardboardBox {
      translation 5.86 1.59 0.051
      name "cardboard box large 3"
      size 0.4 0.4 0.1
    }
    DEF OBSTACLE_CBLA4 CardboardBox {
      translation 5.86 2.06 0.051
      name "cardboard box large 4"
      size 0.4 0.4 0.1
    }
    DEF OBSTACLE_CBLA5 CardboardBox {
      translation 5.86 2.53 0.051
      name "cardboard box large 5"
      size 0.4 0.4 0.1
    }
    DEF OBSTACLE_C1 WoodenChair {
      translation 6.46 0 0
      name "wooden chair 1"
    }
    DEF OBSTACLE_C2 WoodenChair {
      translation 6.46 0.46 0
      name "wooden chair 2"
    }
    DEF OBSTACLE_C3 WoodenChair {
      translation 6.46 0.91 0
      name "wooden chair 3"
    }
    DEF OBSTACLE_C4 WoodenChair {
      translation 6.46 1.38 0
      name "wooden chair 4"
    }
    DEF OBSTACLE_C5 WoodenChair {
      translation 6.46 1.84 0
      name "wooden chair 5"
    }
    DEF OBSTACLE_JJ1 JamJar {
      translation 5.31 -0.16 0
      name "jam jar 1"
    }
    DEF OBSTACLE_JJ2 JamJar {
      translation 5.31 -0.05 0
      name "jam jar 2"
    }
    DEF OBSTACLE_JJ3 JamJar {
      translation 5.31 0.06 0
      name "jam jar 3"
    }
    DEF OBSTACLE_JJ4 JamJar {
      translation 5.31 0.16 0
      name "jam jar 4"
    }
    DEF OBSTACLE_JJ5 JamJar {
      translation 5.31 0.27 0
      name "jam jar 5"
    }
  ]
}
DEF WALLS Group {
  children [
    DEF WALL_1 Solid {
      translation 4.94 5.96488e-06 0.05
      rotation 0 0 1 -1.5707953071795862
      children [
        Shape {
          appearance PBRAppearance {
            roughness 1
            metalness 0.4
          }
          geometry Box {
            size 3.6 0.025 0.1
          }
        }
      ]
      name "wall 1"
    }
    DEF WALL_2 Solid {
      translation 4.99 6.01603e-06 0.05
      rotation 0 0 1 -1.5707953071795862
      children [
        Shape {
          appearance PBRAppearance {
            roughness 1
            metalness 0.4
          }
          geometry Box {
            size 3.6 0.025 0.1
          }
        }
      ]
      name "wall 2"
    }
  ]
}
DEF PATH Group {
  children [
    DEF p0 Solid {
      translation 5.13 6.4235e-07 0.001
      rotation 0 0 1 -1.5707953071795862
      children [
        Shape {
          appearance Appearance {
            material Material {
              transparency 0.75
            }
            texture ImageTexture {
              url [
                "https://avatars.githubusercontent.com/u/57842071?s=256"
              ]
            }
          }
          geometry Plane {
            size 0.12 0.12
          }
        }
      ]
      name "p"
    }
    DEF p1 Solid {
      translation 5.13 0.120001 0.001
      rotation 0 0 1 -1.5707953071795862
      children [
        Shape {
          appearance Appearance {
            material Material {
              transparency 0.75
            }
            texture ImageTexture {
              url [
                "https://avatars.githubusercontent.com/u/57842071?s=256"
              ]
            }
          }
          geometry Plane {
            size 0.12 0.12
          }
        }
      ]
      name "p(1)"
    }
    DEF p2 Solid {
      translation 5.13 0.250001 0.001
      rotation 0 0 1 -1.5707953071795862
      children [
        Shape {
          appearance Appearance {
            material Material {
              transparency 0.75
            }
            texture ImageTexture {
              url [
                "https://avatars.githubusercontent.com/u/57842071?s=256"
              ]
            }
          }
          geometry Plane {
            size 0.12 0.12
          }
        }
      ]
      name "p(2)"
    }
    DEF p3 Solid {
      translation 5.13 0.360001 0.001
      rotation 0 0 1 -1.5707953071795862
      children [
        Shape {
          appearance Appearance {
            material Material {
              transparency 0.75
            }
            texture ImageTexture {
              url [
                "https://avatars.githubusercontent.com/u/57842071?s=256"
              ]
            }
          }
          geometry Plane {
            size 0.12 0.12
          }
        }
      ]
      name "p(3)"
    }
    DEF p4 Solid {
      translation 5.13 0.490001 0.001
      rotation 0 0 1 -1.5707953071795862
      children [
        Shape {
          appearance Appearance {
            material Material {
              transparency 0.75
            }
            texture ImageTexture {
              url [
                "https://avatars.githubusercontent.com/u/57842071?s=256"
              ]
            }
          }
          geometry Plane {
            size 0.12 0.12
          }
        }
      ]
      name "p(4)"
    }
    DEF p5 Solid {
      translation 5.13 0.610001 0.001
      rotation 0 0 1 -1.5707953071795862
      children [
        Shape {
          appearance Appearance {
            material Material {
              transparency 0.75
            }
            texture ImageTexture {
              url [
                "https://avatars.githubusercontent.com/u/57842071?s=256"
              ]
            }
          }
          geometry Plane {
            size 0.12 0.12
          }
        }
      ]
      name "p(5)"
    }
    DEF p6 Solid {
      translation 5.13 0.730001 0.001
      rotation 0 0 1 -1.5707953071795862
      children [
        Shape {
          appearance Appearance {
            material Material {
              transparency 0.75
            }
            texture ImageTexture {
              url [
                "https://avatars.githubusercontent.com/u/57842071?s=256"
              ]
            }
          }
          geometry Plane {
            size 0.12 0.12
          }
        }
      ]
      name "p(6)"
    }
    DEF p7 Solid {
      translation 5.13 0.850001 0.001
      rotation 0 0 1 -1.5707953071795862
      children [
        Shape {
          appearance Appearance {
            material Material {
              transparency 0.75
            }
            texture ImageTexture {
              url [
                "https://avatars.githubusercontent.com/u/57842071?s=256"
              ]
            }
          }
          geometry Plane {
            size 0.12 0.12
          }
        }
      ]
      name "p(7)"
    }
    DEF p8 Solid {
      translation 5.13 0.970001 0.001
      rotation 0 0 1 -1.5707953071795862
      children [
        Shape {
          appearance Appearance {
            material Material {
              transparency 0.75
            }
            texture ImageTexture {
              url [
                "https://avatars.githubusercontent.com/u/57842071?s=256"
              ]
            }
          }
          geometry Plane {
            size 0.12 0.12
          }
        }
      ]
      name "p(8)"
    }
    DEF p9 Solid {
      translation 5.13 1.1 0.001
      rotation 0 0 1 -1.5707953071795862
      children [
        Shape {
          appearance Appearance {
            material Material {
              transparency 0.75
            }
            texture ImageTexture {
              url [
                "https://avatars.githubusercontent.com/u/57842071?s=256"
              ]
            }
          }
          geometry Plane {
            size 0.12 0.12
          }
        }
      ]
      name "p(9)"
    }
    DEF p10 Solid {
      translation 5.13 1.23 0.001
      rotation 0 0 1 -1.5707953071795862
      children [
        Shape {
          appearance Appearance {
            material Material {
              transparency 0.75
            }
            texture ImageTexture {
              url [
                "https://avatars.githubusercontent.com/u/57842071?s=256"
              ]
            }
          }
          geometry Plane {
            size 0.12 0.12
          }
        }
      ]
      name "p(10)"
    }
    DEF p11 Solid {
      translation 5.13 1.36 0.001
      rotation 0 0 1 -1.5707953071795862
      children [
        Shape {
          appearance Appearance {
            material Material {
              transparency 0.75
            }
            texture ImageTexture {
              url [
                "https://avatars.githubusercontent.com/u/57842071?s=256"
              ]
            }
          }
          geometry Plane {
            size 0.12 0.12
          }
        }
      ]
      name "p(11)"
    }
    DEF p12 Solid {
      translation 5.13 1.49 0.001
      rotation 0 0 1 -1.5707953071795862
      children [
        Shape {
          appearance Appearance {
            material Material {
              transparency 0.75
            }
            texture ImageTexture {
              url [
                "https://avatars.githubusercontent.com/u/57842071?s=256"
              ]
            }
          }
          geometry Plane {
            size 0.12 0.12
          }
        }
      ]
      name "p(12)"
    }
    DEF p13 Solid {
      translation 5.13 1.61 0.001
      rotation 0 0 1 -1.5707953071795862
      children [
        Shape {
          appearance Appearance {
            material Material {
              transparency 0.75
            }
            texture ImageTexture {
              url [
                "https://avatars.githubusercontent.com/u/57842071?s=256"
              ]
            }
          }
          geometry Plane {
            size 0.12 0.12
          }
        }
      ]
      name "p(13)"
    }
    DEF p14 Solid {
      translation 5.13 1.74 0.001
      rotation 0 0 1 -1.5707953071795862
      children [
        Shape {
          appearance Appearance {
            material Material {
              transparency 0.75
            }
            texture ImageTexture {
              url [
                "https://avatars.githubusercontent.com/u/57842071?s=256"
              ]
            }
          }
          geometry Plane {
            size 0.12 0.12
          }
        }
      ]
      name "p(14)"
    }
    DEF p15 Solid {
      translation 5.13 1.86 0.001
      rotation 0 0 1 -1.5707953071795862
      children [
        Shape {
          appearance Appearance {
            material Material {
              transparency 0.75
            }
            texture ImageTexture {
              url [
                "https://avatars.githubusercontent.com/u/57842071?s=256"
              ]
            }
          }
          geometry Plane {
            size 0.12 0.12
          }
        }
      ]
      name "p(15)"
    }
  ]
}
